<?xml version="1.0" encoding="utf-8"?>
<!-- This URDF was automatically created by SolidWorks to URDF Exporter! Originally created by Stephen Brawner (brawner@gmail.com) 
     Commit Version: 1.5.1-0-g916b5db  Build Version: 1.5.7152.31018
     For more information, please see http://wiki.ros.org/sw_urdf_exporter -->
<robot
  name="single_joint">
  <link
    name="base_link">
    <inertial>
      <origin
        xyz="0 0 0.015"
        rpy="0 0 0" />
      <mass
        value="0.0" />
      <inertia
        ixx="2.5447E-06"
        ixy="0"
        ixz="6.6104E-39"
        iyy="2.5447E-06"
        iyz="-7.3763E-39"
        izz="1.2723E-06" />
    </inertial>
    <visual>
      <origin
        xyz="0 0 0"
        rpy="0 0 0" />
      <geometry>
        <mesh
          filename="meshes/base_link.STL" />
      </geometry>
      <material
        name="">
        <color
          rgba="0.89804 0.91765 0.92941 1" />
      </material>
    </visual>
    <collision>
      <origin
        xyz="0 0 0"
        rpy="0 0 0" />
      <geometry>
        <mesh
          filename="meshes/base_link.STL" />
      </geometry>
    </collision>
  </link>
  <link
    name="rotary_link">
    <inertial>
      <origin
        xyz="-0.0005312 9.9464E-17 0"
        rpy="0 0 0" />
      <mass
        value="0.23952" />
      <inertia
        ixx="0.00036561"
        ixy="2.4475E-18"
        ixz="-1.9394E-21"
        iyy="0.00035791"
        iyz="1.9489E-21"
        izz="0.00071953" />
    </inertial>
    <visual>
      <origin
        xyz="0 0 0"
        rpy="0 0 0" />
      <geometry>
        <mesh
          filename="meshes/rotary_link.STL" />
      </geometry>
      <material
        name="">
        <color
          rgba="0.89804 0.91765 0.92941 1" />
      </material>
    </visual>
    <collision>
      <origin
        xyz="0 0 0"
        rpy="0 0 0" />
      <geometry>
        <mesh
          filename="meshes/rotary_link.STL" />
      </geometry>
    </collision>
  </link>
  <joint
    name="joint0"
    type="continuous">
    <origin
      xyz="0 0 0.015"
      rpy="0 0 0" />
    <parent
      link="base_link" />
    <child
      link="rotary_link" />
    <axis
      xyz="0 0 1" />
  </joint>
</robot>